2018-04-06 13:47:42,308|ERROR|KeyError|'Traceback (most recent call last):\n  File "C:/Users/nli/PycharmProjects/GA sim/src.py", line 180, in <module>\n    main()\n  File "C:/Users/nli/PycharmProjects/GA sim/src.py", line 173, in main\n    halloffame=hof, verbose=True)\n  File "C:\\Python27\\lib\\site-packages\\deap\\algorithms.py", line 147, in eaSimple\n    fitnesses = toolbox.map(toolbox.evaluate, invalid_ind)\n  File "C:/Users/nli/PycharmProjects/GA sim/src.py", line 106, in eval_SSE\n    result = runSim(input)\n  File "C:/Users/nli/PycharmProjects/GA sim/src.py", line 77, in runSim\n    r = Vissim.Net.VehicleTravelTimeMeasurements.GetMultipleAttributes((\'Name\', genQuery(i)))\n  File "C:\\Python27\\lib\\site-packages\\win32com\\gen_py\\6331B57B-DCD4-4E00-9BFA-D97922D2B1ECx0x9x0\\IVehicleTravelTimeMeasurementContainer.py", line 70, in GetMultipleAttributes\n    return self._ApplyTypes_(1610743817, 1, (12, 0), ((12, 1),), u\'GetMultipleAttributes\', None,AttrIDs\n  File "C:\\Python27\\lib\\site-packages\\win32com\\client\\__init__.py", line 467, in _ApplyTypes_\n    self._oleobj_.InvokeTypes(dispid, 0, wFlags, retType, argTypes, *args),\ncom_error: (-2147352567, \'Exception occurred.\', (0, u\'VISSIM.Vissim.900\', u\'CComBaseContainer::GetMultipleAttributes failed: Object 3 of type Simulation Run does not exist.\', None, 0, -2147352567), None)'|
